<?xml version='1.0'?>

<robot name="my_robot" xmlns:xacro="http://www.ros.org/wiki/xacro">
  
  <xacro:include filename="$(find my_robot)/urdf/my_robot.gazebo" />
<!--Robot colours -->
  <gazebo reference="left_wheel">
    <material>Gazebo/Black</material>
  </gazebo>

  <gazebo reference="right_wheel">
    <material>Gazebo/Black</material>
  </gazebo>

  <gazebo reference="camera">
    <material>Gazebo/Blue</material>
  </gazebo>

  <gazebo reference="chassis">
    <material>Gazebo/Grey</material>
  </gazebo>

  <link name="robot_footprint"></link>
  <!--Robot joints -->
  <joint name="robot_footprint_joint" type="fixed">
    <origin xyz="0 0 0" rpy="0 0 0" />
    <parent link="robot_footprint"/>
    <child link="chassis" />
  </joint>

  <joint name="camera_joint" type="fixed">
    <origin xyz="0.30 0 0.01" rpy="0 0 0" />
    <parent link="chassis"/>
    <child link="camera" />  
    <axis xyz="0 1 0"/> 
  </joint>

  <joint name="hokuyo_joint" type="fixed">
    <origin xyz="0.22 0 0.08" rpy="0 0 0" />
    <parent link="chassis"/>
    <child link="hokuyo" />  
    <axis xyz="0 1 0"/> 
  </joint>

  <joint type="continuous" name="left_wheel_hinge">
    <origin xyz="0 0.25 0" rpy="0 0 0" />
    <parent link="chassis"/>
    <child link="left_wheel" />
    <axis xyz="0 1 0" rpy="0 0 0" />
    <limit effort="100000" velocity="10" />
    <dynamics damping="1.0" friction="2.0" />
  </joint>

  <joint type="continuous" name="right_wheel_hinge">
    <origin xyz="0 -0.25 0" rpy="0 0 0" />
    <parent link="chassis"/>
    <child link="right_wheel" />
    <axis xyz="0 1 0" rpy="0 0 0" />
    <limit effort="100000" velocity="10" />
    <dynamics damping="1.0" friction="2.0" />
  </joint>
  
  <!--Robot camera link -->
  <link name="camera">
    <inertial>
      <mass value="0.1"/>
      <origin xyz="0 0 0" rpy="0 0 0"/>
      <inertia
        ixx="1e-6" ixy="0.0" ixz="0.0"
        iyy="1e-6" iyz="0.0"
        izz="1e-6"
      />
    </inertial>

    <collision>
      <origin xyz="0 0 0" rpy="0 0 0"/>
      <geometry>
        <box size="0.05 0.05 0.05"/>
      </geometry>
    </collision>

    <visual>
      <origin xyz="0 0 0" rpy="0 0 0"/>
      <geometry>
        <box size="0.05 0.05 0.05"/>
      </geometry>
    </visual>
  </link>

<!--Robot laser link -->
  <link name="hokuyo">
    <inertial>
      <mass value="1e-5"/>
      <origin xyz="0 0 0" rpy="0 0 0"/>
      <inertia
        ixx="1e-6" ixy="0.0" ixz="0.0"
        iyy="1e-6" iyz="0.0"
        izz="1e-6"
      />
    </inertial>

    <collision>
      <origin xyz="0 0 0" rpy="0 0 0"/>
      <geometry>
        <box size="0.1 0.1 0.1"/>
      </geometry>
    </collision>

    <visual>
      <origin xyz="0 0 0" rpy="0 0 0"/>
      <geometry>
        <mesh filename="package://my_robot/meshes/hokuyo.dae"/>
      </geometry>
    </visual>

  </link>

<!--Robot left wheel link -->
  <link name="left_wheel">
    <inertial>
      <mass value="2.0"/>
      <origin xyz="0 0 0" rpy="0 1.5707 1.5707"/>
      <inertia
        ixx="0.1" ixy="0.0" ixz="0.0"
        iyy="0.1" iyz="0.0"
        izz="0.1"
      />
    </inertial>

    <collision>
      <origin xyz="0 0 0" rpy="0 1.5707 1.5707"/>
      <geometry>
        <cylinder radius="0.15" length="0.1"/>
      </geometry>
    </collision>

    <visual>
      <origin xyz="0 0 0" rpy="0 1.5707 1.5707"/>
      <geometry>
        <cylinder radius="0.15" length="0.1"/>
      </geometry>
    </visual>

  </link>

<!--Robot right wheel link-->
  <link name="right_wheel">
    <inertial>
      <mass value="2.0"/>
      <origin xyz="0 0 0" rpy="0 1.5707 1.5707"/>
      <inertia
        ixx="0.1" ixy="0.0" ixz="0.0"
        iyy="0.1" iyz="0.0"
        izz="0.1"
      />
    </inertial>

    <collision>
      <origin xyz="0 0 0" rpy="0 1.5707 1.5707"/>
      <geometry>
        <cylinder radius="0.15" length="0.1"/>
      </geometry>
    </collision>

    <visual>
      <origin xyz="0 0 0" rpy="0 1.5707 1.5707"/>
      <geometry>
        <cylinder radius="0.15" length="0.1"/>
      </geometry>
    </visual>

  </link>

<!--Robot chassis link -->
  <link name='chassis'>
    <pose>0 0 0.1 0 0 0</pose>

    <inertial>
      <mass value="40.0"/>
      <origin xyz="0.0 0 0" rpy=" 0 0 0"/>
      <inertia
          ixx="0.1" ixy="0" ixz="0"
          iyy="0.1" iyz="0"
          izz="0.1"
      />
    </inertial>

    <collision name='collision'>
      <origin xyz="0 0 0" rpy=" 0 0 0"/> 
      <geometry>
        <box size=".55 .35 .1"/>
      </geometry>
    </collision>

    <visual name='chassis_visual'>
      <origin xyz="0 0 0" rpy=" 0 0 0"/>
      <geometry>
        <box size=".55 .35 .1"/>
      </geometry>
    </visual>

<!--Robot body top -->

    <collision name='extend_top'>
      <origin xyz="0 0 0.23" rpy=" 0 0 0"/>
      <geometry>
        <box size=".1 .2 0.35"/>
      </geometry>
    </collision>

    <visual name='extend_top_visual'>
      <origin xyz="0 0 0.23" rpy=" 0 0 0"/>
      <geometry>
        <box size=".1 .2 .35"/>
      </geometry>
    </visual>

    <inertial>
      <mass value="5.0"/>
      <origin xyz="0.0 0 0" rpy=" 0 0 0"/>
      <inertia
          ixx="0.1" ixy="0" ixz="0"
          iyy="0.1" iyz="0"
          izz="0.1"
      />
    </inertial>

<!-- Robot cap -->

    <collision name='hat'>
      <origin xyz="0 0 0.35" rpy=" 0 0 0"/>
      <geometry>
        <mesh filename = "package://my_robot/meshes/hat.dae"/>
      </geometry>
    </collision>

    <visual name='hat_visual'>
      <origin xyz="0 0 0.35" rpy=" 0 0 0"/>
      <geometry>
        <mesh filename = "package://my_robot/meshes/hat.dae"/>
      </geometry>
    </visual>

    <inertial>
      <mass value=".5"/>
      <origin xyz="0.0 0 0" rpy=" 0 0 0"/>
      <inertia
          ixx="0.1" ixy="0" ixz="0"
          iyy="0.1" iyz="0"
          izz="0.1"
      />
    </inertial>

<!--Robot left eye -->
    <collision name='left_eye'>
      <origin xyz="0.07 -0.05 0.28" rpy=" 0 0 0"/>
      <geometry>
        <mesh filename = "package://my_robot/meshes/eye.dae"/>
      </geometry>
    </collision>

    <visual name='left_eye_visual'>
      <origin xyz="0.07 -0.05 0.28" rpy=" 0 0 0"/>
      <geometry>
        <mesh filename = "package://my_robot/meshes/eye.dae"/>
      </geometry>
    </visual>

    <inertial>
      <mass value=".5"/>
      <origin xyz="0.0 0 0" rpy=" 0 0 0"/>
      <inertia
          ixx="0.1" ixy="0" ixz="0"
          iyy="0.1" iyz="0"
          izz="0.1"
      />
    </inertial>

<!--Robot right eye -->
    <collision name='right_eye'>
      <origin xyz="0.07 0.05 0.28" rpy=" 0 0 0"/>
      <geometry>
        <mesh filename = "package://my_robot/meshes/eye.dae"/>
      </geometry>
    </collision>

    <visual name='right_eye_visual'>
      <origin xyz="0.07 0.05 0.28" rpy=" 0 0 0"/>
      <geometry>
        <mesh filename = "package://my_robot/meshes/eye.dae"/>
      </geometry>
    </visual>

    <inertial>
      <mass value="0.5"/>
      <origin xyz="0.0 0 0" rpy=" 0 0 0"/>
      <inertia
          ixx="0.1" ixy="0" ixz="0"
          iyy="0.1" iyz="0"
          izz="0.1"
      />
    </inertial>

<!--Robot smiling teeth -->
    <collision name='teeth'>
      <origin xyz="-0.009 0 -0.2" rpy=" 0 0 0"/>
      <geometry>
        <mesh filename = "package://my_robot/meshes/teeth.dae"/>
      </geometry>
    </collision>

    <visual name='teeth_visual'>
      <origin xyz="-0.009 0 -0.2" rpy=" 0 0 0"/>
      <geometry>
        <mesh filename = "package://my_robot/meshes/teeth.dae"/>
      </geometry>
    </visual>

    <inertial>
      <mass value="0.5"/>
      <origin xyz="0.0 0 0" rpy=" 0 0 0"/>
      <inertia
          ixx="0.1" ixy="0" ixz="0"
          iyy="0.1" iyz="0"
          izz="0.1"
      />
    </inertial>

<!--Robot back caster support -->
    <collision name='back_caster_collision'>
      <origin xyz="-0.15 0 -0.05" rpy=" 0 0 0"/>
      <geometry>
        <sphere radius="0.098"/>
      </geometry>
    </collision>

    <visual name='back_caster_visual'>
      <origin xyz="-0.15 0 -0.05" rpy=" 0 0 0"/>
      <geometry>
        <sphere radius="0.098"/>
      </geometry>
    </visual>

<!--Robot front caster support-->
    <collision name='front_caster_collision'>
      <origin xyz="0.15 0 -0.05" rpy=" 0 0 0"/>
      <geometry>
        <sphere radius="0.098"/>
      </geometry>
    </collision>

    <visual name='front_caster_visual'>
      <origin xyz="0.15 0 -0.05" rpy=" 0 0 0"/>
      <geometry>
        <sphere radius="0.098"/>
      </geometry>
    </visual>

  </link>

</robot>
